Workbook

Sheet columnnames
A1: filename | B1: year | C1: col1 | D1: col2 | E1: col3 | F1: col4 | G1: col5 | H1: col6 | I1: col7 | J1: col8 | K1: col9 | L1: col10 | M1: col11 | N1: col12 | O1: col13
A2: Divvy_Stations_2013.csv | B2: 2013 | C2: id | D2: name | E2: latitude | F2: longitude | G2: dpcapacity | H2: landmark | I2: online date
A3: Divvy_Trips_2013.csv | B3: 2013 | C3: trip_id | D3: starttime | E3: stoptime | F3: bikeid | G3: tripduration | H3: from_station_id | I3: from_station_name | J3: to_station_id | K3: to_station_name | L3: usertype | M3: gender | N3: birthday
A4: Divvy_Stations_2014-Q3Q4.csv | B4: 2014 | C4: id | D4: name | E4: latitude | F4: longitude | G4: dpcapacity | H4: dateCreated
A5: Divvy_Trips_2014_Q1Q2.csv | B5: 2014 | C5: trip_id | D5: starttime | E5: stoptime | F5: bikeid | G5: tripduration | H5: from_station_id | I5: from_station_name | J5: to_station_id | K5: to_station_name | L5: usertype | M5: gender | N5: birthyear
A6: Divvy_Trips_2014-Q3-07.csv | B6: 2014 | C6: trip_id | D6: starttime | E6: stoptime | F6: bikeid | G6: tripduration | H6: from_station_id | I6: from_station_name | J6: to_station_id | K6: to_station_name | L6: usertype | M6: gender | N6: birthyear
A7: Divvy_Trips_2014-Q3-0809.csv | B7: 2014 | C7: trip_id | D7: starttime | E7: stoptime | F7: bikeid | G7: tripduration | H7: from_station_id | I7: from_station_name | J7: to_station_id | K7: to_station_name | L7: usertype | M7: gender | N7: birthyear
A8: Divvy_Trips_2014-Q4.csv | B8: 2014 | C8: trip_id | D8: starttime | E8: stoptime | F8: bikeid | G8: tripduration | H8: from_station_id | I8: from_station_name | J8: to_station_id | K8: to_station_name | L8: usertype | M8: gender | N8: birthyear
A9: Divvy_Stations_2015.csv | B9: 2015 | C9: id | D9: name | E9: latitude | F9: longitude | G9: dpcapacity | H9: landmark
A10: Divvy_Trips_2015_07.csv | B10: 2015 | C10: trip_id | D10: starttime | E10: stoptime | F10: bikeid | G10: tripduration | H10: from_station_id | I10: from_station_name | J10: to_station_id | K10: to_station_name | L10: usertype | M10: gender | N10: birthyear
A11: Divvy_Trips_2015_08.csv | B11: 2015 | C11: trip_id | D11: starttime | E11: stoptime | F11: bikeid | G11: tripduration | H11: from_station_id | I11: from_station_name | J11: to_station_id | K11: to_station_name | L11: usertype | M11: gender | N11: birthyear
A12: Divvy_Trips_2015_09.csv | B12: 2015 | C12: trip_id | D12: starttime | E12: stoptime | F12: bikeid | G12: tripduration | H12: from_station_id | I12: from_station_name | J12: to_station_id | K12: to_station_name | L12: usertype | M12: gender | N12: birthyear
A13: Divvy_Trips_2015_Q4.csv | B13: 2015 | C13: trip_id | D13: starttime | E13: stoptime | F13: bikeid | G13: tripduration | H13: from_station_id | I13: from_station_name | J13: to_station_id | K13: to_station_name | L13: usertype | M13: gender | N13: birthyear
A14: Divvy_Trips_2015-Q1.csv | B14: 2015 | C14: trip_id | D14: starttime | E14: stoptime | F14: bikeid | G14: tripduration | H14: from_station_id | I14: from_station_name | J14: to_station_id | K14: to_station_name | L14: usertype | M14: gender | N14: birthyear
A15: Divvy_Trips_2015-Q2.csv | B15: 2015 | C15: trip_id | D15: starttime | E15: stoptime | F15: bikeid | G15: tripduration | H15: from_station_id | I15: from_station_name | J15: to_station_id | K15: to_station_name | L15: usertype | M15: gender | N15: birthyear
A16: Divvy_Stations_2016_Q1Q2.csv | B16: 2016 | C16: id | D16: name | E16: latitude | F16: longitude | G16: dpcapacity | H16: online_date
A17: Divvy_Stations_2016_Q3.csv | B17: 2016 | C17: id | D17: name | E17: latitude | F17: longitude | G17: dpcapacity | H17: online_date
A18: Divvy_Stations_2016_Q4.csv | B18: 2016 | C18: id | D18: name | E18: latitude | F18: longitude | G18: dpcapacity | H18: online_date
A19: Divvy_Trips_2016_04.csv | B19: 2016 | C19: trip_id | D19: starttime | E19: stoptime | F19: bikeid | G19: tripduration | H19: from_station_id | I19: from_station_name | J19: to_station_id | K19: to_station_name | L19: usertype | M19: gender | N19: birthyear
A20: Divvy_Trips_2016_05.csv | B20: 2016 | C20: trip_id | D20: starttime | E20: stoptime | F20: bikeid | G20: tripduration | H20: from_station_id | I20: from_station_name | J20: to_station_id | K20: to_station_name | L20: usertype | M20: gender | N20: birthyear
A21: Divvy_Trips_2016_06.csv | B21: 2016 | C21: trip_id | D21: starttime | E21: stoptime | F21: bikeid | G21: tripduration | H21: from_station_id | I21: from_station_name | J21: to_station_id | K21: to_station_name | L21: usertype | M21: gender | N21: birthyear
A22: Divvy_Trips_2016_Q1.csv | B22: 2016 | C22: trip_id | D22: starttime | E22: stoptime | F22: bikeid | G22: tripduration | H22: from_station_id | I22: from_station_name | J22: to_station_id | K22: to_station_name | L22: usertype | M22: gender | N22: birthyear
A23: Divvy_Trips_2016_Q3.csv | B23: 2016 | C23: trip_id | D23: starttime | E23: stoptime | F23: bikeid | G23: tripduration | H23: from_station_id | I23: from_station_name | J23: to_station_id | K23: to_station_name | L23: usertype | M23: gender | N23: birthyear
A24: Divvy_Trips_2016_Q4.csv | B24: 2016 | C24: trip_id | D24: starttime | E24: stoptime | F24: bikeid | G24: tripduration | H24: from_station_id | I24: from_station_name | J24: to_station_id | K24: to_station_name | L24: usertype | M24: gender | N24: birthyear
A25: Divvy_Stations_2017_Q1Q2.csv | B25: 2017 | C25: id | D25: name | E25: city | F25: latitude | G25: longitude | H25: dpcapacity | I25: online_date
A26: Divvy_Stations_2017_Q3Q4.csv | B26: 2017 | C26: id | D26: name | E26: city | F26: latitude | G26: longitude | H26: dpcapacity | I26: online_date | J26: Unnamed: 7
A27: Divvy_Trips_2017_Q1.csv | B27: 2017 | C27: trip_id | D27: start_time | E27: end_time | F27: bikeid | G27: tripduration | H27: from_station_id | I27: from_station_name | J27: to_station_id | K27: to_station_name | L27: usertype | M27: gender | N27: birthyear
A28: Divvy_Trips_2017_Q2.csv | B28: 2017 | C28: trip_id | D28: start_time | E28: end_time | F28: bikeid | G28: tripduration | H28: from_station_id | I28: from_station_name | J28: to_station_id | K28: to_station_name | L28: usertype | M28: gender | N28: birthyear
A29: Divvy_Trips_2017_Q3.csv | B29: 2017 | C29: trip_id | D29: start_time | E29: end_time | F29: bikeid | G29: tripduration | H29: from_station_id | I29: from_station_name | J29: to_station_id | K29: to_station_name | L29: usertype | M29: gender | N29: birthyear
A30: Divvy_Trips_2017_Q4.csv | B30: 2017 | C30: trip_id | D30: start_time | E30: end_time | F30: bikeid | G30: tripduration | H30: from_station_id | I30: from_station_name | J30: to_station_id | K30: to_station_name | L30: usertype | M30: gender | N30: birthyear
A31: Divvy_Trips_2018_Q1.csv | B31: 2018 | C31: 01 - Rental Details Rental ID | D31: 01 - Rental Details Local Start Time | E31: 01 - Rental Details Local End Time | F31: 01 - Rental Details Bike ID | G31: 01 - Rental Details Duration In Seconds Uncapped | H31: 03 - Rental Start Station ID | I31: 03 - Rental Start Station Name | J31: 02 - Rental End Station ID | K31: 02 - Rental End Station Name | L31: User Type | M31: Member Gender | N31: 05 - Member Details Member Birthday Year
A32: Divvy_Trips_2018_Q2.csv | B32: 2018 | C32: trip_id | D32: start_time | E32: end_time | F32: bikeid | G32: tripduration | H32: from_station_id | I32: from_station_name | J32: to_station_id | K32: to_station_name | L32: usertype | M32: gender | N32: birthyear
A33: Divvy_Trips_2018_Q3.csv | B33: 2018 | C33: trip_id | D33: start_time | E33: end_time | F33: bikeid | G33: tripduration | H33: from_station_id | I33: from_station_name | J33: to_station_id | K33: to_station_name | L33: usertype | M33: gender | N33: birthyear
A34: Divvy_Trips_2018_Q4.csv | B34: 2018 | C34: trip_id | D34: start_time | E34: end_time | F34: bikeid | G34: tripduration | H34: from_station_id | I34: from_station_name | J34: to_station_id | K34: to_station_name | L34: usertype | M34: gender | N34: birthyear
A35: Divvy_Trips_2019_Q1.csv | B35: 2019 | C35: trip_id | D35: start_time | E35: end_time | F35: bikeid | G35: tripduration | H35: from_station_id | I35: from_station_name | J35: to_station_id | K35: to_station_name | L35: usertype | M35: gender | N35: birthyear
A36: Divvy_Trips_2019_Q2.csv | B36: 2019 | C36: 01 - Rental Details Rental ID | D36: 01 - Rental Details Local Start Time | E36: 01 - Rental Details Local End Time | F36: 01 - Rental Details Bike ID | G36: 01 - Rental Details Duration In Seconds Uncapped | H36: 03 - Rental Start Station ID | I36: 03 - Rental Start Station Name | J36: 02 - Rental End Station ID | K36: 02 - Rental End Station Name | L36: User Type | M36: Member Gender | N36: 05 - Member Details Member Birthday Year
A37: Divvy_Trips_2019_Q3.csv | B37: 2019 | C37: trip_id | D37: start_time | E37: end_time | F37: bikeid | G37: tripduration | H37: from_station_id | I37: from_station_name | J37: to_station_id | K37: to_station_name | L37: usertype | M37: gender | N37: birthyear
A38: Divvy_Trips_2019_Q4.csv | B38: 2019 | C38: trip_id | D38: start_time | E38: end_time | F38: bikeid | G38: tripduration | H38: from_station_id | I38: from_station_name | J38: to_station_id | K38: to_station_name | L38: usertype | M38: gender | N38: birthyear
A39: 202004-divvy-tripdata.csv | B39: =LEFT(A39, 4) -> 2020 | C39: ride_id | D39: rideable_type | E39: started_at | F39: ended_at | G39: start_station_name | H39: start_station_id | I39: end_station_name | J39: end_station_id | K39: start_lat | L39: start_lng | M39: end_lat | N39: end_lng | O39: member_casual
A40: 202005-divvy-tripdata.csv | B40: =LEFT(A40, 4) -> 2020 | C40: ride_id | D40: rideable_type | E40: started_at | F40: ended_at | G40: start_station_name | H40: start_station_id | I40: end_station_name | J40: end_station_id | K40: start_lat | L40: start_lng | M40: end_lat | N40: end_lng | O40: member_casual
...

Sheet compare
A1: filename | B1: year | C1: col1 | D1: col2 | E1: col3 | F1: col4 | G1: col5 | H1: col6 | I1: col7 | J1: col8 | K1: col9 | L1: col10 | M1: col11 | N1: col12 | O1: col13
A2: Divvy_Stations_2013.csv | B2: 2013 | C2: =columnnames!C2 & "(" & datasample!C2 & ")" -> id(13) | D2: =columnnames!D2 & "(" & datasample!D2 & ")" -> name(Wilton Ave & Diversey Pkwy) | E2: =columnnames!E2 & "(" & datasample!E2 & ")" -> latitude(41.93250008) | F2: =columnnames!F2 & "(" & datasample!F2 & ")" -> longitude(-87.65268082) | G2: =columnnames!G2 & "(" & datasample!G2 & ")" -> dpcapacity(19) | H2: =columnnames!H2 & "(" & datasample!H2 & ")" -> landmark(66) | I2: =columnnames!I2 & "(" & datasample!I2 & ")" -> online date(6/28/2013) | J2: =columnnames!J2 & "(" & datasample!J2 & ")" -> () | ... O2: =columnnames!O2 & "(" & datasample!O2 & ")" -> ()
A3: Divvy_Trips_2013.csv | B3: 2013 | C3: =columnnames!C3 & "(" & datasample!C3 & ")" -> trip_id(4275) | D3: =columnnames!D3 & "(" & datasample!D3 & ")" -> starttime(2013-06-27 14:44) | E3: =columnnames!E3 & "(" & datasample!E3 & ")" -> stoptime(2013-06-27 14:45) | F3: =columnnames!F3 & "(" & datasample!F3 & ")" -> bikeid(77) | G3: =columnnames!G3 & "(" & datasample!G3 & ")" -> tripduration(64) | H3: =columnnames!H3 & "(" & datasample!H3 & ")" -> from_station_id(32) | I3: =columnnames!I3 & "(" & datasample!I3 & ")" -> from_station_name(Racine Ave & Congress Pkwy) | J3: =columnnames!J3 & "(" & datasample!J3 & ")" -> to_station_id(32) | ... O3: =columnnames!O3 & "(" & datasample!O3 & ")" -> ()
A4: Divvy_Stations_2014-Q3Q4.csv | B4: 2014 | C4: =columnnames!C4 & "(" & datasample!C4 & ")" -> id(13) | D4: =columnnames!D4 & "(" & datasample!D4 & ")" -> name(Wilton Ave & Diversey Pkwy) | E4: =columnnames!E4 & "(" & datasample!E4 & ")" -> latitude(41.93250008) | F4: =columnnames!F4 & "(" & datasample!F4 & ")" -> longitude(-87.65268082) | G4: =columnnames!G4 & "(" & datasample!G4 & ")" -> dpcapacity(19) | H4: =columnnames!H4 & "(" & datasample!H4 & ")" -> dateCreated(6/22/2013 18:29) | I4: =columnnames!I4 & "(" & datasample!I4 & ")" -> () | J4: =columnnames!J4 & "(" & datasample!J4 & ")" -> () | ... O4: =columnnames!O4 & "(" & datasample!O4 & ")" -> ()
A5: Divvy_Trips_2014_Q1Q2.csv | B5: 2014 | C5: =columnnames!C5 & "(" & datasample!C5 & ")" -> trip_id(2355133) | D5: =columnnames!D5 & "(" & datasample!D5 & ")" -> starttime(6/30/2014 23:56) | E5: =columnnames!E5 & "(" & datasample!E5 & ")" -> stoptime(7/1/2014 0:00) | F5: =columnnames!F5 & "(" & datasample!F5 & ")" -> bikeid(2217) | G5: =columnnames!G5 & "(" & datasample!G5 & ")" -> tripduration(263) | H5: =columnnames!H5 & "(" & datasample!H5 & ")" -> from_station_id(282) | I5: =columnnames!I5 & "(" & datasample!I5 & ")" -> from_station_name(Halsted St & Maxwell St) | J5: =columnnames!J5 & "(" & datasample!J5 & ")" -> to_station_id(22) | ... O5: =columnnames!O5 & "(" & datasample!O5 & ")" -> ()
A6: Divvy_Trips_2014-Q3-07.csv | B6: 2014 | C6: =columnnames!C6 & "(" & datasample!C6 & ")" -> trip_id(2886258) | D6: =columnnames!D6 & "(" & datasample!D6 & ")" -> starttime(7/31/2014 23:58) | E6: =columnnames!E6 & "(" & datasample!E6 & ")" -> stoptime(8/1/2014 0:07) | F6: =columnnames!F6 & "(" & datasample!F6 & ")" -> bikeid(2403) | G6: =columnnames!G6 & "(" & datasample!G6 & ")" -> tripduration(495) | H6: =columnnames!H6 & "(" & datasample!H6 & ")" -> from_station_id(98) | I6: =columnnames!I6 & "(" & datasample!I6 & ")" -> from_station_name(LaSalle St & Washington St) | J6: =columnnames!J6 & "(" & datasample!J6 & ")" -> to_station_id(106) | ... O6: =columnnames!O6 & "(" & datasample!O6 & ")" -> ()
A7: Divvy_Trips_2014-Q3-0809.csv | B7: 2014 | C7: =columnnames!C7 & "(" & datasample!C7 & ")" -> trip_id(3810749) | D7: =columnnames!D7 & "(" & datasample!D7 & ")" -> starttime(9/30/2014 23:59) | E7: =columnnames!E7 & "(" & datasample!E7 & ")" -> stoptime(10/1/2014 0:01) | F7: =columnnames!F7 & "(" & datasample!F7 & ")" -> bikeid(989) | G7: =columnnames!G7 & "(" & datasample!G7 & ")" -> tripduration(142) | H7: =columnnames!H7 & "(" & datasample!H7 & ")" -> from_station_id(277) | I7: =columnnames!I7 & "(" & datasample!I7 & ")" -> from_station_name(Ashland Ave & Grand Ave) | J7: =columnnames!J7 & "(" & datasample!J7 & ")" -> to_station_id(285) | ... O7: =columnnames!O7 & "(" & datasample!O7 & ")" -> ()
A8: Divvy_Trips_2014-Q4.csv | B8: 2014 | C8: =columnnames!C8 & "(" & datasample!C8 & ")" -> trip_id(4413166) | D8: =columnnames!D8 & "(" & datasample!D8 & ")" -> starttime(12/31/2014 23:50) | E8: =columnnames!E8 & "(" & datasample!E8 & ")" -> stoptime(12/31/2014 23:52) | F8: =columnnames!F8 & "(" & datasample!F8 & ")" -> bikeid(1153) | G8: =columnnames!G8 & "(" & datasample!G8 & ")" -> tripduration(161) | H8: =columnnames!H8 & "(" & datasample!H8 & ")" -> from_station_id(264) | I8: =columnnames!I8 & "(" & datasample!I8 & ")" -> from_station_name(Stetson Ave & South Water St) | J8: =columnnames!J8 & "(" & datasample!J8 & ")" -> to_station_id(44) | ... O8: =columnnames!O8 & "(" & datasample!O8 & ")" -> ()
A9: Divvy_Stations_2015.csv | B9: 2015 | C9: =columnnames!C9 & "(" & datasample!C9 & ")" -> id(3) | D9: =columnnames!D9 & "(" & datasample!D9 & ")" -> name(Shedd Aquarium) | E9: =columnnames!E9 & "(" & datasample!E9 & ")" -> latitude(41.86722596) | F9: =columnnames!F9 & "(" & datasample!F9 & ")" -> longitude(-87.61535539) | G9: =columnnames!G9 & "(" & datasample!G9 & ")" -> dpcapacity(31) | H9: =columnnames!H9 & "(" & datasample!H9 & ")" -> landmark(544) | I9: =columnnames!I9 & "(" & datasample!I9 & ")" -> () | J9: =columnnames!J9 & "(" & datasample!J9 & ")" -> () | ... O9: =columnnames!O9 & "(" & datasample!O9 & ")" -> ()
A10: Divvy_Trips_2015_07.csv | B10: 2015 | C10: =columnnames!C10 & "(" & datasample!C10 & ")" -> trip_id(6611091) | D10: =columnnames!D10 & "(" & datasample!D10 & ")" -> starttime(7/31/2015 23:59) | E10: =columnnames!E10 & "(" & datasample!E10 & ")" -> stoptime(8/1/2015 0:22) | F10: =columnnames!F10 & "(" & datasample!F10 & ")" -> bikeid(3747) | G10: =columnnames!G10 & "(" & datasample!G10 & ")" -> tripduration(1378) | H10: =columnnames!H10 & "(" & datasample!H10 & ")" -> from_station_id(177) | I10: =columnnames!I10 & "(" & datasample!I10 & ")" -> from_station_name(Theater on the Lake) | J10: =columnnames!J10 & "(" & datasample!J10 & ")" -> to_station_id(312) | ... O10: =columnnames!O10 & "(" & datasample!O10 & ")" -> ()
A11: Divvy_Trips_2015_08.csv | B11: 2015 | C11: =columnnames!C11 & "(" & datasample!C11 & ")" -> trip_id(7221406) | D11: =columnnames!D11 & "(" & datasample!D11 & ")" -> starttime(8/31/2015 23:58) | E11: =columnnames!E11 & "(" & datasample!E11 & ")" -> stoptime(9/1/2015 0:26) | F11: =columnnames!F11 & "(" & datasample!F11 & ")" -> bikeid(431) | G11: =columnnames!G11 & "(" & datasample!G11 & ")" -> tripduration(1676) | H11: =columnnames!H11 & "(" & datasample!H11 & ")" -> from_station_id(511) | I11: =columnnames!I11 & "(" & datasample!I11 & ")" -> from_station_name(Albany Ave & Bloomingdale Ave) | J11: =columnnames!J11 & "(" & datasample!J11 & ")" -> to_station_id(58) | ... O11: =columnnames!O11 & "(" & datasample!O11 & ")" -> ()
A12: Divvy_Trips_2015_09.csv | B12: 2015 | C12: =columnnames!C12 & "(" & datasample!C12 & ")" -> trip_id(7745069) | D12: =columnnames!D12 & "(" & datasample!D12 & ")" -> starttime(9/30/2015 23:59) | E12: =columnnames!E12 & "(" & datasample!E12 & ")" -> stoptime(10/1/2015 0:07) | F12: =columnnames!F12 & "(" & datasample!F12 & ")" -> bikeid(1414) | G12: =columnnames!G12 & "(" & datasample!G12 & ")" -> tripduration(476) | H12: =columnnames!H12 & "(" & datasample!H12 & ")" -> from_station_id(229) | I12: =columnnames!I12 & "(" & datasample!I12 & ")" -> from_station_name(Southport Ave & Roscoe St) | J12: =columnnames!J12 & "(" & datasample!J12 & ")" -> to_station_id(165) | ... O12: =columnnames!O12 & "(" & datasample!O12 & ")" -> ()
A13: Divvy_Trips_2015_Q4.csv | B13: 2015 | C13: =columnnames!C13 & "(" & datasample!C13 & ")" -> trip_id(8547209) | D13: =columnnames!D13 & "(" & datasample!D13 & ")" -> starttime(12/31/2015 23:47) | E13: =columnnames!E13 & "(" & datasample!E13 & ")" -> stoptime(12/31/2015 23:53) | F13: =columnnames!F13 & "(" & datasample!F13 & ")" -> bikeid(3866) | G13: =columnnames!G13 & "(" & datasample!G13 & ")" -> tripduration(334) | H13: =columnnames!H13 & "(" & datasample!H13 & ")" -> from_station_id(299) | I13: =columnnames!I13 & "(" & datasample!I13 & ")" -> from_station_name(Halsted St & Roscoe St) | J13: =columnnames!J13 & "(" & datasample!J13 & ")" -> to_station_id(117) | ... O13: =columnnames!O13 & "(" & datasample!O13 & ")" -> ()
... A38: Divvy_Trips_2019_Q4.csv | B38: 2019 | C38: =columnnames!C38 & "(" & datasample!C38 & ")" -> trip_id(25223641) | D38: =columnnames!D38 & "(" & datasample!D38 & ")" -> start_time(2019-10-01 00:02:16) | E38: =columnnames!E38 & "(" & datasample!E38 & ")" -> end_time(2019-10-01 00:06:34) | F38: =columnnames!F38 & "(" & datasample!F38 & ")" -> bikeid(6328) | G38: =columnnames!G38 & "(" & datasample!G38 & ")" -> tripduration(258.0) | H38: =columnnames!H38 & "(" & datasample!H38 & ")" -> from_station_id(19) | I38: =columnnames!I38 & "(" & datasample!I38 & ")" -> from_station_name(Throop (Loomis) St & Taylor St) | J38: =columnnames!J38 & "(" & datasample!J38 & ")" -> to_station_id(241) | ... O38: =columnnames!O38 & "(" & datasample!O38 & ")" -> ()
A39: 202004-divvy-tripdata.csv | B39: =LEFT(A39, 4) -> 2020 | C39: =columnnames!C39 & "(" & datasample!C39 & ")" -> ride_id(5405B80E996FF60D) | D39: =columnnames!D39 & "(" & datasample!D39 & ")" -> rideable_type(docked_bike) | E39: =columnnames!E39 & "(" & datasample!E39 & ")" -> started_at(2020-04-17 17:08:54) | F39: =columnnames!F39 & "(" & datasample!F39 & ")" -> ended_at(2020-04-17 17:17:03) | G39: =columnnames!G39 & "(" & datasample!G39 & ")" -> start_station_name(Drake Ave & Fullerton Ave) | H39: =columnnames!H39 & "(" & datasample!H39 & ")" -> start_station_id(503) | I39: =columnnames!I39 & "(" & datasample!I39 & ")" -> end_station_name(Kosciuszko Park) | J39: =columnnames!J39 & "(" & datasample!J39 & ")" -> end_station_id(499) | ... O39: =columnnames!O39 & "(" & datasample!O39 & ")" -> member_casual(member)
A40: 202005-divvy-tripdata.csv | B40: =LEFT(A40, 4) -> 2020 | C40: =columnnames!C40 & "(" & datasample!C40 & ")" -> ride_id(7A50CCAF1EDDB28F) | D40: =columnnames!D40 & "(" & datasample!D40 & ")" -> rideable_type(docked_bike) | E40: =columnnames!E40 & "(" & datasample!E40 & ")" -> started_at(2020-05-25 10:47:11) | F40: =columnnames!F40 & "(" & datasample!F40 & ")" -> ended_at(2020-05-25 11:05:40) | G40: =columnnames!G40 & "(" & datasample!G40 & ")" -> start_station_name(Clark St & Wrightwood Ave) | H40: =columnnames!H40 & "(" & datasample!H40 & ")" -> start_station_id(340) | I40: =columnnames!I40 & "(" & datasample!I40 & ")" -> end_station_name(Clark St & Leland Ave) | J40: =columnnames!J40 & "(" & datasample!J40 & ")" -> end_station_id(326) | ... O40: =columnnames!O40 & "(" & datasample!O40 & ")" -> member_casual(casual)
A41: 202006-divvy-tripdata.csv | B41: =LEFT(A41, 4) -> 2020 | C41: =columnnames!C41 & "(" & datasample!C41 & ")" -> ride_id(9A191EB2C751D85D) | D41: =columnnames!D41 & "(" & datasample!D41 & ")" -> rideable_type(docked_bike) | E41: =columnnames!E41 & "(" & datasample!E41 & ")" -> started_at(2020-06-26 07:26:10) | F41: =columnnames!F41 & "(" & datasample!F41 & ")" -> ended_at(2020-06-26 07:31:58) | G41: =columnnames!G41 & "(" & datasample!G41 & ")" -> start_station_name(Federal St & Polk St) | H41: =columnnames!H41 & "(" & datasample!H41 & ")" -> start_station_id(41) | I41: =columnnames!I41 & "(" & datasample!I41 & ")" -> end_station_name(Daley Center Plaza) | J41: =columnnames!J41 & "(" & datasample!J41 & ")" -> end_station_id(81) | ... O41: =columnnames!O41 & "(" & datasample!O41 & ")" -> member_casual(member)
A42: 202007-divvy-tripdata.csv | B42: =LEFT(A42, 4) -> 2020 | C42: =columnnames!C42 & "(" & datasample!C42 & ")" -> ride_id(BEC9C9FBA0D4CF1B) | D42: =columnnames!D42 & "(" & datasample!D42 & ")" -> rideable_type(docked_bike) | E42: =columnnames!E42 & "(" & datasample!E42 & ")" -> started_at(2020-07-24 23:56:30) | F42: =columnnames!F42 & "(" & datasample!F42 & ")" -> ended_at(2020-07-25 00:20:17) | G42: =columnnames!G42 & "(" & datasample!G42 & ")" -> start_station_name(Halsted St & Roscoe St) | H42: =columnnames!H42 & "(" & datasample!H42 & ")" -> start_station_id(299) | I42: =columnnames!I42 & "(" & datasample!I42 & ")" -> end_station_name(Broadway & Ridge Ave) | J42: =columnnames!J42 & "(" & datasample!J42 & ")" -> end_station_id(461) | ... O42: =columnnames!O42 & "(" & datasample!O42 & ")" -> member_casual(member)
A43: 202008-divvy-tripdata.csv | B43: =LEFT(A43, 4) -> 2020 | C43: =columnnames!C43 & "(" & datasample!C43 & ")" -> ride_id(2A3AEF1AB9054D8B) | D43: =columnnames!D43 & "(" & datasample!D43 & ")" -> rideable_type(electric_bike) | E43: =columnnames!E43 & "(" & datasample!E43 & ")" -> started_at(2020-08-27 18:46:04) | F43: =columnnames!F43 & "(" & datasample!F43 & ")" -> ended_at(2020-08-27 19:54:51) | G43: =columnnames!G43 & "(" & datasample!G43 & ")" -> start_station_name(Michigan Ave & 14th St) | H43: =columnnames!H43 & "(" & datasample!H43 & ")" -> start_station_id(168) | I43: =columnnames!I43 & "(" & datasample!I43 & ")" -> end_station_name(Michigan Ave & 14th St) | J43: =columnnames!J43 & "(" & datasample!J43 & ")" -> end_station_id(168) | ... O43: =columnnames!O43 & "(" & datasample!O43 & ")" -> member_casual(casual)
A44: 202009-divvy-tripdata.csv | B44: =LEFT(A44, 4) -> 2020 | C44: =columnnames!C44 & "(" & datasample!C44 & ")" -> ride_id(A7FB70B4AFC6CAF2) | D44: =columnnames!D44 & "(" & datasample!D44 & ")" -> rideable_type(electric_bike) | E44: =columnnames!E44 & "(" & datasample!E44 & ")" -> started_at(2020-09-17 15:07:31) | F44: =columnnames!F44 & "(" & datasample!F44 & ")" -> ended_at(2020-09-17 15:07:45) | G44: =columnnames!G44 & "(" & datasample!G44 & ")" -> start_station_name(W Oakdale Ave & N Broadway) | H44: =columnnames!H44 & "(" & datasample!H44 & ")" -> start_station_id() | I44: =columnnames!I44 & "(" & datasample!I44 & ")" -> end_station_name(W Oakdale Ave & N Broadway) | J44: =columnnames!J44 & "(" & datasample!J44 & ")" -> end_station_id() | ... O44: =columnnames!O44 & "(" & datasample!O44 & ")" -> member_casual(casual)
A45: 202010-divvy-tripdata.csv | B45: =LEFT(A45, 4) -> 2020 | C45: =columnnames!C45 & "(" & datasample!C45 & ")" -> ride_id(DF450C72FD109C01) | D45: =columnnames!D45 & "(" & datasample!D45 & ")" -> rideable_type(electric_bike) | E45: =columnnames!E45 & "(" & datasample!E45 & ")" -> started_at(2020-10-31 23:50:08) | F45: =columnnames!F45 & "(" & datasample!F45 & ")" -> ended_at(2020-11-01 00:04:16) | G45: =columnnames!G45 & "(" & datasample!G45 & ")" -> start_station_name(Southport Ave & Waveland Ave) | H45: =columnnames!H45 & "(" & datasample!H45 & ")" -> start_station_id(227) | I45: =columnnames!I45 & "(" & datasample!I45 & ")" -> end_station_name(Kedzie Ave & Milwaukee Ave) | J45: =columnnames!J45 & "(" & datasample!J45 & ")" -> end_station_id(260) | ... O45: =columnnames!O45 & "(" & datasample!O45 & ")" -> member_casual(casual)
A46: 202011-divvy-tripdata.csv | B46: =LEFT(A46, 4) -> 2020 | C46: =columnnames!C46 & "(" & datasample!C46 & ")" -> ride_id(96A7A7A4BDE4F82D) | D46: =columnnames!D46 & "(" & datasample!D46 & ")" -> rideable_type(electric_bike) | E46: =columnnames!E46 & "(" & datasample!E46 & ")" -> started_at(2020-11-01 10:03:26) | F46: =columnnames!F46 & "(" & datasample!F46 & ")" -> ended_at(2020-11-01 10:14:45) | G46: =columnnames!G46 & "(" & datasample!G46 & ")" -> start_station_name(Franklin St & Illinois St) | H46: =columnnames!H46 & "(" & datasample!H46 & ")" -> start_station_id(672) | I46: =columnnames!I46 & "(" & datasample!I46 & ")" -> end_station_name(Noble St & Milwaukee Ave) | J46: =columnnames!J46 & "(" & datasample!J46 & ")" -> end_station_id(29) | ... O46: =columnnames!O46 & "(" & datasample!O46 & ")" -> member_casual(casual)
A47: 202012-divvy-tripdata.csv | B47: =LEFT(A47, 4) -> 2020 | C47: =columnnames!C47 & "(" & datasample!C47 & ")" -> ride_id(158A465D4E74C54A) | D47: =columnnames!D47 & "(" & datasample!D47 & ")" -> rideable_type(electric_bike) | E47: =columnnames!E47 & "(" & datasample!E47 & ")" -> started_at(2020-12-18 17:37:15) | F47: =columnnames!F47 & "(" & datasample!F47 & ")" -> ended_at(2020-12-18 17:44:19) | G47: =columnnames!G47 & "(" & datasample!G47 & ")" -> start_station_name() | H47: =columnnames!H47 & "(" & datasample!H47 & ")" -> start_station_id() | I47: =columnnames!I47 & "(" & datasample!I47 & ")" -> end_station_name() | J47: =columnnames!J47 & "(" & datasample!J47 & ")" -> end_station_id() | ... O47: =columnnames!O47 & "(" & datasample!O47 & ")" -> member_casual(member)
A48: Divvy_Trips_2020_Q1.csv | B48: 2020 | C48: =columnnames!C48 & "(" & datasample!C48 & ")" -> ride_id(8FED874C809DC021) | D48: =columnnames!D48 & "(" & datasample!D48 & ")" -> rideable_type(docked_bike) | E48: =columnnames!E48 & "(" & datasample!E48 & ")" -> started_at(2020-01-30 14:22:39) | F48: =columnnames!F48 & "(" & datasample!F48 & ")" -> ended_at(2020-01-30 14:26:22) | G48: =columnnames!G48 & "(" & datasample!G48 & ")" -> start_station_name(Clark St & Montrose Ave) | H48: =columnnames!H48 & "(" & datasample!H48 & ")" -> start_station_id(234) | I48: =columnnames!I48 & "(" & datasample!I48 & ")" -> end_station_name(Southport Ave & Irving Park Rd) | J48: =columnnames!J48 & "(" & datasample!J48 & ")" -> end_station_id(318) | ... O48: =columnnames!O48 & "(" & datasample!O48 & ")" -> member_casual(member)
A49: 202101-divvy-tripdata.csv | B49: =LEFT(A49, 4) -> 2021 | C49: =columnnames!C49 & "(" & datasample!C49 & ")" -> ride_id(DC88F20C2C55F27F) | D49: =columnnames!D49 & "(" & datasample!D49 & ")" -> rideable_type(electric_bike) | E49: =columnnames!E49 & "(" & datasample!E49 & ")" -> started_at(2021-01-27 18:43:08) | F49: =columnnames!F49 & "(" & datasample!F49 & ")" -> ended_at(2021-01-27 18:47:12) | G49: =columnnames!G49 & "(" & datasample!G49 & ")" -> start_station_name(California Ave & Cortez St) | H49: =columnnames!H49 & "(" & datasample!H49 & ")" -> start_station_id(17660) | I49: =columnnames!I49 & "(" & datasample!I49 & ")" -> end_station_name() | J49: =columnnames!J49 & "(" & datasample!J49 & ")" -> end_station_id() | ... O49: =columnnames!O49 & "(" & datasample!O49 & ")" -> member_casual(member)
A50: 202102-divvy-tripdata.csv | B50: =LEFT(A50, 4) -> 2021 | C50: =columnnames!C50 & "(" & datasample!C50 & ")" -> ride_id(0FEFDE2603568365) | D50: =columnnames!D50 & "(" & datasample!D50 & ")" -> rideable_type(classic_bike) | E50: =columnnames!E50 & "(" & datasample!E50 & ")" -> started_at(2021-02-14 17:52:38) | F50: =columnnames!F50 & "(" & datasample!F50 & ")" -> ended_at(2021-02-14 18:12:09) | G50: =columnnames!G50 & "(" & datasample!G50 & ")" -> start_station_name(Glenwood Ave & Touhy Ave) | H50: =columnnames!H50 & "(" & datasample!H50 & ")" -> start_station_id(525) | I50: =columnnames!I50 & "(" & datasample!I50 & ")" -> end_station_name(Bosworth Ave & Howard St) | J50: =columnnames!J50 & "(" & datasample!J50 & ")" -> end_station_id(16806) | ... O50: =columnnames!O50 & "(" & datasample!O50 & ")" -> member_casual(casual)
A51: 202103-divvy-tripdata.csv | B51: =LEFT(A51, 4) -> 2021 | C51: =columnnames!C51 & "(" & datasample!C51 & ")" -> ride_id(30D9DC61227D1AF3) | D51: =columnnames!D51 & "(" & datasample!D51 & ")" -> rideable_type(classic_bike) | E51: =columnnames!E51 & "(" & datasample!E51 & ")" -> started_at(2021-03-28 01:26:28) | F51: =columnnames!F51 & "(" & datasample!F51 & ")" -> ended_at(2021-03-28 01:36:55) | G51: =columnnames!G51 & "(" & datasample!G51 & ")" -> start_station_name(Humboldt Blvd & Armitage Ave) | H51: =columnnames!H51 & "(" & datasample!H51 & ")" -> start_station_id(15651) | I51: =columnnames!I51 & "(" & datasample!I51 & ")" -> end_station_name(Central Park Ave & Bloomingdale Ave) | J51: =columnnames!J51 & "(" & datasample!J51 & ")" -> end_station_id(18017) | ... O51: =columnnames!O51 & "(" & datasample!O51 & ")" -> member_casual(casual)
A52: 202104-divvy-tripdata.csv | B52: =LEFT(A52, 4) -> 2021 | C52: =columnnames!C52 & "(" & datasample!C52 & ")" -> ride_id(1E0145613A209000) | D52: =columnnames!D52 & "(" & datasample!D52 & ")" -> rideable_type(docked_bike) | E52: =columnnames!E52 & "(" & datasample!E52 & ")" -> started_at(2021-04-27 17:27:11) | F52: =columnnames!F52 & "(" & datasample!F52 & ")" -> ended_at(2021-04-27 18:31:29) | G52: =columnnames!G52 & "(" & datasample!G52 & ")" -> start_station_name(Dorchester Ave & 49th St) | H52: =columnnames!H52 & "(" & datasample!H52 & ")" -> start_station_id(KA1503000069) | I52: =columnnames!I52 & "(" & datasample!I52 & ")" -> end_station_name(Dorchester Ave & 49th St) | J52: =columnnames!J52 & "(" & datasample!J52 & ")" -> end_station_id(KA1503000069) | ... O52: =columnnames!O52 & "(" & datasample!O52 & ")" -> member_casual(casual)
A53: 202105-divvy-tripdata.csv | B53: =LEFT(A53, 4) -> 2021 | C53: =columnnames!C53 & "(" & datasample!C53 & ")" -> ride_id(DD59FDCE0ACACAF3) | D53: =columnnames!D53 & "(" & datasample!D53 & ")" -> rideable_type(electric_bike) | E53: =columnnames!E53 & "(" & datasample!E53 & ")" -> started_at(2021-05-30 11:29:14) | F53: =columnnames!F53 & "(" & datasample!F53 & ")" -> ended_at(2021-05-30 12:14:09) | G53: =columnnames!G53 & "(" & datasample!G53 & ")" -> start_station_name() | H53: =columnnames!H53 & "(" & datasample!H53 & ")" -> start_station_id() | I53: =columnnames!I53 & "(" & datasample!I53 & ")" -> end_station_name() | J53: =columnnames!J53 & "(" & datasample!J53 & ")" -> end_station_id() | ... O53: =columnnames!O53 & "(" & datasample!O53 & ")" -> member_casual(casual)
A54: 202106-divvy-tripdata.csv | B54: =LEFT(A54, 4) -> 2021 | C54: =columnnames!C54 & "(" & datasample!C54 & ")" -> ride_id(06048DCFC8520CAF) | D54: =columnnames!D54 & "(" & datasample!D54 & ")" -> rideable_type(electric_bike) | E54: =columnnames!E54 & "(" & datasample!E54 & ")" -> started_at(2021-06-04 11:18:02) | F54: =columnnames!F54 & "(" & datasample!F54 & ")" -> ended_at(2021-06-04 11:24:19) | G54: =columnnames!G54 & "(" & datasample!G54 & ")" -> start_station_name() | H54: =columnnames!H54 & "(" & datasample!H54 & ")" -> start_station_id() | I54: =columnnames!I54 & "(" & datasample!I54 & ")" -> end_station_name() | J54: =columnnames!J54 & "(" & datasample!J54 & ")" -> end_station_id() | ... O54: =columnnames!O54 & "(" & datasample!O54 & ")" -> member_casual(member)
A55: 202107-divvy-tripdata.csv | B55: =LEFT(A55, 4) -> 2021 | C55: =columnnames!C55 & "(" & datasample!C55 & ")" -> ride_id(B2D5583A5A5E76EE) | D55: =columnnames!D55 & "(" & datasample!D55 & ")" -> rideable_type(classic_bike) | E55: =columnnames!E55 & "(" & datasample!E55 & ")" -> started_at(2021-07-07 16:57:42) | F55: =columnnames!F55 & "(" & datasample!F55 & ")" -> ended_at(2021-07-07 17:16:09) | G55: =columnnames!G55 & "(" & datasample!G55 & ")" -> start_station_name(California Ave & Cortez St) | H55: =columnnames!H55 & "(" & datasample!H55 & ")" -> start_station_id(17660) | I55: =columnnames!I55 & "(" & datasample!I55 & ")" -> end_station_name(Wood St & Hubbard St) | J55: =columnnames!J55 & "(" & datasample!J55 & ")" -> end_station_id(13432) | ... O55: =columnnames!O55 & "(" & datasample!O55 & ")" -> member_casual(casual)
A56: 202108-divvy-tripdata.csv | B56: =LEFT(A56, 4) -> 2021 | C56: =columnnames!C56 & "(" & datasample!C56 & ")" -> ride_id(EAFCCCFB0A3FC5A1) | D56: =columnnames!D56 & "(" & datasample!D56 & ")" -> rideable_type(electric_bike) | E56: =columnnames!E56 & "(" & datasample!E56 & ")" -> started_at(2021-08-10 17:23:14) | F56: =columnnames!F56 & "(" & datasample!F56 & ")" -> ended_at(2021-08-10 17:39:24) | G56: =columnnames!G56 & "(" & datasample!G56 & ")" -> start_station_name() | H56: =columnnames!H56 & "(" & datasample!H56 & ")" -> start_station_id() | I56: =columnnames!I56 & "(" & datasample!I56 & ")" -> end_station_name() | J56: =columnnames!J56 & "(" & datasample!J56 & ")" -> end_station_id() | ... O56: =columnnames!O56 & "(" & datasample!O56 & ")" -> member_casual(member)
A57: 202109-divvy-tripdata.csv | B57: =LEFT(A57, 4) -> 2021 | C57: =columnnames!C57 & "(" & datasample!C57 & ")" -> ride_id(F930E2C6872D6B32) | D57: =columnnames!D57 & "(" & datasample!D57 & ")" -> rideable_type(electric_bike) | E57: =columnnames!E57 & "(" & datasample!E57 & ")" -> started_at(2021-09-28 14:24:51) | F57: =columnnames!F57 & "(" & datasample!F57 & ")" -> ended_at(2021-09-28 14:40:05) | G57: =columnnames!G57 & "(" & datasample!G57 & ")" -> start_station_name() | H57: =columnnames!H57 & "(" & datasample!H57 & ")" -> start_station_id() | I57: =columnnames!I57 & "(" & datasample!I57 & ")" -> end_station_name() | J57: =columnnames!J57 & "(" & datasample!J57 & ")" -> end_station_id() | ... O57: =columnnames!O57 & "(" & datasample!O57 & ")" -> member_casual(casual)
A58: 202110-divvy-tripdata.csv | B58: =LEFT(A58, 4) -> 2021 | C58: =columnnames!C58 & "(" & datasample!C58 & ")" -> ride_id(4471C70731AB2E45) | D58: =columnnames!D58 & "(" & datasample!D58 & ")" -> rideable_type(electric_bike) | E58: =columnnames!E58 & "(" & datasample!E58 & ")" -> started_at(2021-10-21 09:12:37) | F58: =columnnames!F58 & "(" & datasample!F58 & ")" -> ended_at(2021-10-21 09:14:14) | G58: =columnnames!G58 & "(" & datasample!G58 & ")" -> start_station_name() | H58: =columnnames!H58 & "(" & datasample!H58 & ")" -> start_station_id() | I58: =columnnames!I58 & "(" & datasample!I58 & ")" -> end_station_name() | J58: =columnnames!J58 & "(" & datasample!J58 & ")" -> end_station_id() | ... O58: =columnnames!O58 & "(" & datasample!O58 & ")" -> member_casual(member)
A59: 202111-divvy-tripdata.csv | B59: =LEFT(A59, 4) -> 2021 | C59: =columnnames!C59 & "(" & datasample!C59 & ")" -> ride_id(90854840DFD508BA) | D59: =columnnames!D59 & "(" & datasample!D59 & ")" -> rideable_type(electric_bike) | E59: =columnnames!E59 & "(" & datasample!E59 & ")" -> started_at(2021-11-27 13:38:25) | F59: =columnnames!F59 & "(" & datasample!F59 & ")" -> ended_at(2021-11-27 13:56:10) | G59: =columnnames!G59 & "(" & datasample!G59 & ")" -> start_station_name() | H59: =columnnames!H59 & "(" & datasample!H59 & ")" -> start_station_id() | I59: =columnnames!I59 & "(" & datasample!I59 & ")" -> end_station_name() | J59: =columnnames!J59 & "(" & datasample!J59 & ")" -> end_station_id() | ... O59: =columnnames!O59 & "(" & datasample!O59 & ")" -> member_casual(casual)
A60: 202112-divvy-tripdata.csv | B60: =LEFT(A60, 4) -> 2021 | C60: =columnnames!C60 & "(" & datasample!C60 & ")" -> ride_id(73A77762838B32FD) | D60: =columnnames!D60 & "(" & datasample!D60 & ")" -> rideable_type(electric_bike) | E60: =columnnames!E60 & "(" & datasample!E60 & ")" -> started_at(2021-12-11 03:43:29) | F60: =columnnames!F60 & "(" & datasample!F60 & ")" -> ended_at(2021-12-11 04:10:23) | G60: =columnnames!G60 & "(" & datasample!G60 & ")" -> start_station_name(LaSalle Dr & Huron St) | H60: =columnnames!H60 & "(" & datasample!H60 & ")" -> start_station_id(KP1705001026) | I60: =columnnames!I60 & "(" & datasample!I60 & ")" -> end_station_name(Clarendon Ave & Leland Ave) | J60: =columnnames!J60 & "(" & datasample!J60 & ")" -> end_station_id(TA1307000119) | ... O60: =columnnames!O60 & "(" & datasample!O60 & ")" -> member_casual(casual)
... A113: 202605-divvy-tripdata.csv | B113: =LEFT(A113, 4) -> 2026 | C113: =columnnames!C113 & "(" & datasample!C113 & ")" -> ride_id(746948BC4E29B6D0) | D113: =columnnames!D113 & "(" & datasample!D113 & ")" -> rideable_type(electric_bike) | E113: =columnnames!E113 & "(" & datasample!E113 & ")" -> started_at(2026-05-20 11:37:45.232) | F113: =columnnames!F113 & "(" & datasample!F113 & ")" -> ended_at(2026-05-20 11:51:43.399) | G113: =columnnames!G113 & "(" & datasample!G113 & ")" -> start_station_name() | H113: =columnnames!H113 & "(" & datasample!H113 & ")" -> start_station_id() | I113: =columnnames!I113 & "(" & datasample!I113 & ")" -> end_station_name() | J113: =columnnames!J113 & "(" & datasample!J113 & ")" -> end_station_id() | ... O113: =columnnames!O113 & "(" & datasample!O113 & ")" -> member_casual(casual)

Sheet datatypes
A1: filename | B1: year | C1: col1 | D1: col2 | E1: col3 | F1: col4 | G1: col5 | H1: col6 | I1: col7 | J1: col8 | K1: col9 | L1: col10 | M1: col11 | N1: col12 | O1: col13
A2: Divvy_Stations_2013.csv | B2: 2013 | C2: int64 | D2: object | E2: float64 | F2: float64 | G2: int64 | H2: int64 | I2: object
A3: Divvy_Trips_2013.csv | B3: 2013 | C3: int64 | D3: object | E3: object | F3: int64 | G3: int64 | H3: int64 | I3: object | J3: int64 | K3: object | L3: object | M3: object | N3: float64
A4: Divvy_Stations_2014-Q3Q4.csv | B4: 2014 | C4: int64 | D4: object | E4: float64 | F4: float64 | G4: int64 | H4: object
A5: Divvy_Trips_2014_Q1Q2.csv | B5: 2014 | C5: int64 | D5: object | E5: object | F5: int64 | G5: int64 | H5: int64 | I5: object | J5: int64 | K5: object | L5: object | M5: object | N5: float64
A6: Divvy_Trips_2014-Q3-07.csv | B6: 2014 | C6: int64 | D6: object | E6: object | F6: int64 | G6: int64 | H6: int64 | I6: object | J6: int64 | K6: object | L6: object | M6: object | N6: float64
A7: Divvy_Trips_2014-Q3-0809.csv | B7: 2014 | C7: int64 | D7: object | E7: object | F7: int64 | G7: int64 | H7: int64 | I7: object | J7: int64 | K7: object | L7: object | M7: object | N7: float64
A8: Divvy_Trips_2014-Q4.csv | B8: 2014 | C8: int64 | D8: object | E8: object | F8: int64 | G8: int64 | H8: int64 | I8: object | J8: int64 | K8: object | L8: object | M8: object | N8: float64
A9: Divvy_Stations_2015.csv | B9: 2015 | C9: int64 | D9: object | E9: float64 | F9: float64 | G9: int64 | H9: int64
A10: Divvy_Trips_2015_07.csv | B10: 2015 | C10: int64 | D10: object | E10: object | F10: int64 | G10: int64 | H10: int64 | I10: object | J10: int64 | K10: object | L10: object | M10: object | N10: float64
A11: Divvy_Trips_2015_08.csv | B11: 2015 | C11: int64 | D11: object | E11: object | F11: int64 | G11: int64 | H11: int64 | I11: object | J11: int64 | K11: object | L11: object | M11: object | N11: float64
A12: Divvy_Trips_2015_09.csv | B12: 2015 | C12: int64 | D12: object | E12: object | F12: int64 | G12: int64 | H12: int64 | I12: object | J12: int64 | K12: object | L12: object | M12: object | N12: float64
A13: Divvy_Trips_2015_Q4.csv | B13: 2015 | C13: int64 | D13: object | E13: object | F13: int64 | G13: int64 | H13: int64 | I13: object | J13: int64 | K13: object | L13: object | M13: object | N13: float64
A14: Divvy_Trips_2015-Q1.csv | B14: 2015 | C14: int64 | D14: object | E14: object | F14: int64 | G14: int64 | H14: int64 | I14: object | J14: int64 | K14: object | L14: object | M14: object | N14: float64
A15: Divvy_Trips_2015-Q2.csv | B15: 2015 | C15: int64 | D15: object | E15: object | F15: int64 | G15: int64 | H15: int64 | I15: object | J15: int64 | K15: object | L15: object | M15: object | N15: float64
A16: Divvy_Stations_2016_Q1Q2.csv | B16: 2016 | C16: int64 | D16: object | E16: float64 | F16: float64 | G16: int64 | H16: object
A17: Divvy_Stations_2016_Q3.csv | B17: 2016 | C17: int64 | D17: object | E17: float64 | F17: float64 | G17: int64 | H17: object
A18: Divvy_Stations_2016_Q4.csv | B18: 2016 | C18: int64 | D18: object | E18: float64 | F18: float64 | G18: int64 | H18: object
A19: Divvy_Trips_2016_04.csv | B19: 2016 | C19: int64 | D19: object | E19: object | F19: int64 | G19: int64 | H19: int64 | I19: object | J19: int64 | K19: object | L19: object | M19: object | N19: float64
A20: Divvy_Trips_2016_05.csv | B20: 2016 | C20: int64 | D20: object | E20: object | F20: int64 | G20: int64 | H20: int64 | I20: object | J20: int64 | K20: object | L20: object | M20: object | N20: float64
A21: Divvy_Trips_2016_06.csv | B21: 2016 | C21: int64 | D21: object | E21: object | F21: int64 | G21: int64 | H21: int64 | I21: object | J21: int64 | K21: object | L21: object | M21: object | N21: float64
A22: Divvy_Trips_2016_Q1.csv | B22: 2016 | C22: int64 | D22: object | E22: object | F22: int64 | G22: int64 | H22: int64 | I22: object | J22: int64 | K22: object | L22: object | M22: object | N22: float64
A23: Divvy_Trips_2016_Q3.csv | B23: 2016 | C23: int64 | D23: object | E23: object | F23: int64 | G23: int64 | H23: int64 | I23: object | J23: int64 | K23: object | L23: object | M23: object | N23: float64
A24: Divvy_Trips_2016_Q4.csv | B24: 2016 | C24: int64 | D24: object | E24: object | F24: int64 | G24: int64 | H24: int64 | I24: object | J24: int64 | K24: object | L24: object | M24: object | N24: float64
A25: Divvy_Stations_2017_Q1Q2.csv | B25: 2017 | C25: int64 | D25: object | E25: object | F25: float64 | G25: float64 | H25: int64 | I25: object
A26: Divvy_Stations_2017_Q3Q4.csv | B26: 2017 | C26: int64 | D26: object | E26: object | F26: float64 | G26: float64 | H26: int64 | I26: object | J26: float64
A27: Divvy_Trips_2017_Q1.csv | B27: 2017 | C27: int64 | D27: object | E27: object | F27: int64 | G27: int64 | H27: int64 | I27: object | J27: int64 | K27: object | L27: object | M27: object | N27: float64
A28: Divvy_Trips_2017_Q2.csv | B28: 2017 | C28: int64 | D28: object | E28: object | F28: int64 | G28: int64 | H28: int64 | I28: object | J28: int64 | K28: object | L28: object | M28: object | N28: float64
A29: Divvy_Trips_2017_Q3.csv | B29: 2017 | C29: int64 | D29: object | E29: object | F29: int64 | G29: int64 | H29: int64 | I29: object | J29: int64 | K29: object | L29: object | M29: object | N29: float64
A30: Divvy_Trips_2017_Q4.csv | B30: 2017 | C30: int64 | D30: object | E30: object | F30: int64 | G30: int64 | H30: int64 | I30: object | J30: int64 | K30: object | L30: object | M30: object | N30: float64
A31: Divvy_Trips_2018_Q1.csv | B31: 2018 | C31: int64 | D31: object | E31: object | F31: int64 | G31: object | H31: int64 | I31: object | J31: int64 | K31: object | L31: object | M31: object | N31: float64
A32: Divvy_Trips_2018_Q2.csv | B32: 2018 | C32: int64 | D32: object | E32: object | F32: int64 | G32: object | H32: int64 | I32: object | J32: int64 | K32: object | L32: object | M32: object | N32: float64
A33: Divvy_Trips_2018_Q3.csv | B33: 2018 | C33: int64 | D33: object | E33: object | F33: int64 | G33: object | H33: int64 | I33: object | J33: int64 | K33: object | L33: object | M33: object | N33: float64
A34: Divvy_Trips_2018_Q4.csv | B34: 2018 | C34: int64 | D34: object | E34: object | F34: int64 | G34: object | H34: int64 | I34: object | J34: int64 | K34: object | L34: object | M34: object | N34: float64
A35: Divvy_Trips_2019_Q1.csv | B35: 2019 | C35: int64 | D35: object | E35: object | F35: int64 | G35: object | H35: int64 | I35: object | J35: int64 | K35: object | L35: object | M35: object | N35: float64
A36: Divvy_Trips_2019_Q2.csv | B36: 2019 | C36: int64 | D36: object | E36: object | F36: int64 | G36: object | H36: int64 | I36: object | J36: int64 | K36: object | L36: object | M36: object | N36: float64
A37: Divvy_Trips_2019_Q3.csv | B37: 2019 | C37: int64 | D37: object | E37: object | F37: int64 | G37: object | H37: int64 | I37: object | J37: int64 | K37: object | L37: object | M37: object | N37: float64
A38: Divvy_Trips_2019_Q4.csv | B38: 2019 | C38: int64 | D38: object | E38: object | F38: int64 | G38: object | H38: int64 | I38: object | J38: int64 | K38: object | L38: object | M38: object | N38: float64
A39: 202004-divvy-tripdata.csv | B39: 2020 | C39: object | D39: object | E39: object | F39: object | G39: object | H39: int64 | I39: object | J39: float64 | K39: float64 | L39: float64 | M39: float64 | N39: float64 | O39: object
A40: 202005-divvy-tripdata.csv | B40: 2020 | C40: object | D40: object | E40: object | F40: object | G40: object | H40: int64 | I40: object | J40: float64 | K40: float64 | L40: float64 | M40: float64 | N40: float64 | O40: object
...

Sheet datasample
A1: filename | B1: year | C1: col1 | D1: col2 | E1: col3 | F1: col4 | G1: col5 | H1: col6 | I1: col7 | J1: col8 | K1: col9 | L1: col10 | M1: col11 | N1: col12 | O1: col13
A2: Divvy_Stations_2013.csv | B2: 2013 | C2: 13 | D2: Wilton Ave & Diversey Pkwy | E2: 41.9325 | F2: -87.652681 | G2: 19 | H2: 66 | I2: 6/28/2013
A3: Divvy_Trips_2013.csv | B3: 2013 | C3: 4275 | D3: 2013-06-27 14:44 | E3: 2013-06-27 14:45 | F3: 77 | G3: 64 | H3: 32 | I3: Racine Ave & Congress Pkwy | J3: 32 | K3: Racine Ave & Congress Pkwy | L3: Customer
A4: Divvy_Stations_2014-Q3Q4.csv | B4: 2014 | C4: 13 | D4: Wilton Ave & Diversey Pkwy | E4: 41.9325 | F4: -87.652681 | G4: 19 | H4: 6/22/2013 18:29
A5: Divvy_Trips_2014_Q1Q2.csv | B5: 2014 | C5: 2355133 | D5: 6/30/2014 23:56 | E5: 7/1/2014 0:00 | F5: 2217 | G5: 263 | H5: 282 | I5: Halsted St & Maxwell St | J5: 22 | K5: May St & Taylor St | L5: Subscriber | M5: Male | N5: 1992
A6: Divvy_Trips_2014-Q3-07.csv | B6: 2014 | C6: 2886258 | D6: 7/31/2014 23:58 | E6: 8/1/2014 0:07 | F6: 2403 | G6: 495 | H6: 98 | I6: LaSalle St & Washington St | J6: 106 | K6: State St & Pearson St | L6: Subscriber | M6: Male | N6: 1974
A7: Divvy_Trips_2014-Q3-0809.csv | B7: 2014 | C7: 3810749 | D7: 9/30/2014 23:59 | E7: 10/1/2014 0:01 | F7: 989 | G7: 142 | H7: 277 | I7: Ashland Ave & Grand Ave | J7: 285 | K7: Wood St & Grand Ave | L7: Subscriber | M7: Male | N7: 1983
A8: Divvy_Trips_2014-Q4.csv | B8: 2014 | C8: 4413166 | D8: 12/31/2014 23:50 | E8: 12/31/2014 23:52 | F8: 1153 | G8: 161 | H8: 264 | I8: Stetson Ave & South Water St | J8: 44 | K8: State St & Randolph St | L8: Subscriber | M8: Male | N8: 1984
A9: Divvy_Stations_2015.csv | B9: 2015 | C9: 3 | D9: Shedd Aquarium | E9: 41.867226 | F9: -87.615355 | G9: 31 | H9: 544
A10: Divvy_Trips_2015_07.csv | B10: 2015 | C10: 6611091 | D10: 7/31/2015 23:59 | E10: 8/1/2015 0:22 | F10: 3747 | G10: 1378 | H10: 177 | I10: Theater on the Lake | J10: 312 | K10: Clarendon Ave & Gordon Ter | L10: Subscriber | M10: Male | N10: 1980
A11: Divvy_Trips_2015_08.csv | B11: 2015 | C11: 7221406 | D11: 8/31/2015 23:58 | E11: 9/1/2015 0:26 | F11: 431 | G11: 1676 | H11: 511 | I11: Albany Ave & Bloomingdale Ave | J11: 58 | K11: Marshfield Ave & Cortland St | L11: Customer
A12: Divvy_Trips_2015_09.csv | B12: 2015 | C12: 7745069 | D12: 9/30/2015 23:59 | E12: 10/1/2015 0:07 | F12: 1414 | G12: 476 | H12: 229 | I12: Southport Ave & Roscoe St | J12: 165 | K12: Clark St & Grace St | L12: Subscriber | M12: Female | N12: 1983
A13: Divvy_Trips_2015_Q4.csv | B13: 2015 | C13: 8547209 | D13: 12/31/2015 23:47 | E13: 12/31/2015 23:53 | F13: 3866 | G13: 334 | H13: 299 | I13: Halsted St & Roscoe St | J13: 117 | K13: Wilton Ave & Belmont Ave | L13: Subscriber | M13: Female | N13: 1991
A14: Divvy_Trips_2015-Q1.csv | B14: 2015 | C14: 4738450 | D14: 3/31/2015 23:59 | E14: 4/1/2015 0:15 | F14: 537 | G14: 940 | H14: 43 | I14: Michigan Ave & Washington St | J14: 85 | K14: Michigan Ave & Oak St | L14: Customer
A15: Divvy_Trips_2015-Q2.csv | B15: 2015 | C15: 5943499 | D15: 6/30/2015 23:59 | E15: 7/1/2015 0:23 | F15: 4209 | G15: 1428 | H15: 490 | I15: Troy St & Elston Ave | J15: 227 | K15: Southport Ave & Waveland Ave | L15: Customer
A16: Divvy_Stations_2016_Q1Q2.csv | B16: 2016 | C16: 101 | D16: 63rd St Beach | E16: 41.781016 | F16: -87.57612 | G16: 23 | H16: 4/20/2015
A17: Divvy_Stations_2016_Q3.csv | B17: 2016 | C17: 101 | D17: 63rd St Beach | E17: 41.781016 | F17: -87.57612 | G17: 23 | H17: 4/20/2015
A18: Divvy_Stations_2016_Q4.csv | B18: 2016 | C18: 101 | D18: 63rd St Beach | E18: 41.781016 | F18: -87.57612 | G18: 23 | H18: 4/20/2015
A19: Divvy_Trips_2016_04.csv | B19: 2016 | C19: 9379900 | D19: 4/30/2016 23:58 | E19: 5/1/2016 0:07 | F19: 3583 | G19: 556 | H19: 349 | I19: Halsted St & Wrightwood Ave | J19: 165 | K19: Clark St & Grace St | L19: Subscriber | M19: Male | N19: 1991
A20: Divvy_Trips_2016_05.csv | B20: 2016 | C20: 9835708 | D20: 5/31/2016 23:57 | E20: 6/1/2016 0:14 | F20: 1207 | G20: 1035 | H20: 22 | I20: May St & Taylor St | J20: 282 | K20: Halsted St & Maxwell St | L20: Subscriber | M20: Male | N20: 1993
A21: Divvy_Trips_2016_06.csv | B21: 2016 | C21: 10426656 | D21: 6/30/2016 23:58 | E21: 7/1/2016 0:14 | F21: 1858 | G21: 967 | H21: 90 | I21: Millennium Park | J21: 90 | K21: Millennium Park | L21: Customer
A22: Divvy_Trips_2016_Q1.csv | B22: 2016 | C22: 9080550 | D22: 3/31/2016 23:46 | E22: 3/31/2016 23:57 | F22: 4831 | G22: 649 | H22: 128 | I22: Damen Ave & Chicago Ave | J22: 213 | K22: Leavitt St & North Ave | L22: Subscriber | M22: Male | N22: 1980
A23: Divvy_Trips_2016_Q3.csv | B23: 2016 | C23: 12150159 | D23: 9/30/2016 23:59:58 | E23: 10/1/2016 00:04:09 | F23: 2589 | G23: 251 | H23: 383 | I23: Ashland Ave & Harrison St | J23: 320 | K23: Loomis St & Lexington St | L23: Subscriber | M23: Female | N23: 1990
A24: Divvy_Trips_2016_Q4.csv | B24: 2016 | C24: 12979227 | D24: 12/31/2016 23:53:18 | E24: 1/1/2017 00:08:13 | F24: 5114 | G24: 895 | H24: 195 | I24: Columbus Dr & Randolph St | J24: 25 | K24: Michigan Ave & Pearson St | L24: Customer
A25: Divvy_Stations_2017_Q1Q2.csv | B25: 2017 | C25: 101 | D25: 63rd St Beach | E25: Chicago | F25: 41.781016 | G25: -87.57612 | H25: 23 | I25: 7/16/2013 01:27:50
A26: Divvy_Stations_2017_Q3Q4.csv | B26: 2017 | C26: 3 | D26: Shedd Aquarium | E26: Chicago | F26: 41.867226 | G26: -87.615355 | H26: 55 | I26: 6/10/2013 10:44
A27: Divvy_Trips_2017_Q1.csv | B27: 2017 | C27: 13518904 | D27: 3/31/2017 23:56:25 | E27: 4/1/2017 00:00:21 | F27: 4408 | G27: 236 | H27: 199 | I27: Wabash Ave & Grand Ave | J27: 26 | K27: McClurg Ct & Illinois St | L27: Subscriber | M27: Male | N27: 1990
A28: Divvy_Trips_2017_Q2.csv | B28: 2017 | C28: 14853212 | D28: 6/30/2017 23:59:28 | E28: 7/1/2017 00:07:10 | F28: 1909 | G28: 462 | H28: 165 | I28: Clark St & Grace St | J28: 234 | K28: Clark St & Montrose Ave | L28: Subscriber | M28: Female | N28: 1968
A29: Divvy_Trips_2017_Q3.csv | B29: 2017 | C29: 16734064 | D29: 9/30/2017 23:59:53 | E29: 10/1/2017 00:05:47 | F29: 3048 | G29: 354 | H29: 216 | I29: California Ave & Division St | J29: 259 | K29: California Ave & Francis Pl | L29: Subscriber | M29: Male | N29: 1979
A30: Divvy_Trips_2017_Q4.csv | B30: 2017 | C30: 17536700 | D30: 12/31/2017 23:54 | E30: 1/1/2018 0:18 | F30: 5975 | G30: 1402 | H30: 145 | I30: Mies van der Rohe Way & Chestnut St | J30: 145 | K30: Mies van der Rohe Way & Chestnut St | L30: Customer
A31: Divvy_Trips_2018_Q1.csv | B31: 2018 | C31: 17536703 | D31: 2018-01-01 00:41:35 | E31: 2018-01-01 00:47:52 | F31: 5367 | G31: 377.0 | H31: 253 | I31: Winthrop Ave & Lawrence Ave | J31: 325 | K31: Clark St & Winnemac Ave (Temp) | L31: Subscriber | M31: Male | N31: 1984
A32: Divvy_Trips_2018_Q2.csv | B32: 2018 | C32: 18000528 | D32: 2018-04-01 00:06:42 | E32: 2018-04-01 00:27:07 | F32: 5000 | G32: 1,225.0 | H32: 157 | I32: Lake Shore Dr & Wellington Ave | J32: 190 | K32: Southport Ave & Wrightwood Ave | L32: Subscriber | M32: Male | N32: 1965
A33: Divvy_Trips_2018_Q3.csv | B33: 2018 | C33: 19244623 | D33: 2018-07-01 00:00:13 | E33: 2018-07-01 00:06:39 | F33: 93 | G33: 386.0 | H33: 153 | I33: Southport Ave & Wellington Ave | J33: 250 | K33: Ashland Ave & Wellington Ave | L33: Subscriber | M33: Male | N33: 1986
A34: Divvy_Trips_2018_Q4.csv | B34: 2018 | C34: 20983531 | D34: 2018-10-01 00:03:59 | E34: 2018-10-01 00:10:55 | F34: 847 | G34: 416.0 | H34: 13 | I34: Wilton Ave & Diversey Pkwy | J34: 144 | K34: Larrabee St & Webster Ave | L34: Subscriber | M34: Female | N34: 1982
A35: Divvy_Trips_2019_Q1.csv | B35: 2019 | C35: 21742444 | D35: 2019-01-01 00:08:13 | E35: 2019-01-01 00:15:34 | F35: 4386 | G35: 441.0 | H35: 44 | I35: State St & Randolph St | J35: 624 | K35: Dearborn St & Van Buren St (*) | L35: Subscriber | M35: Female | N35: 1990
A36: Divvy_Trips_2019_Q2.csv | B36: 2019 | C36: 22178530 | D36: 2019-04-01 00:03:02 | E36: 2019-04-01 00:20:30 | F36: 6226 | G36: 1,048.0 | H36: 317 | I36: Wood St & Taylor St | J36: 59 | K36: Wabash Ave & Roosevelt Rd | L36: Subscriber | M36: Female | N36: 1984
A37: Divvy_Trips_2019_Q3.csv | B37: 2019 | C37: 23479389 | D37: 2019-07-01 00:01:16 | E37: 2019-07-01 00:18:44 | F37: 5353 | G37: 1,048.0 | H37: 381 | I37: Western Ave & Monroe St | J37: 203 | K37: Western Ave & 21st St | L37: Customer
A38: Divvy_Trips_2019_Q4.csv | B38: 2019 | C38: 25223641 | D38: 2019-10-01 00:02:16 | E38: 2019-10-01 00:06:34 | F38: 6328 | G38: 258.0 | H38: 19 | I38: Throop (Loomis) St & Taylor St | J38: 241 | K38: Morgan St & Polk St | L38: Subscriber | M38: Male | N38: 1998
A39: 202004-divvy-tripdata.csv | B39: 2020 | C39: 5405B80E996FF60D | D39: docked_bike | E39: 2020-04-17 17:08:54 | F39: 2020-04-17 17:17:03 | G39: Drake Ave & Fullerton Ave | H39: 503 | I39: Kosciuszko Park | J39: 499 | K39: 41.9244 | L39: -87.7154 | M39: 41.9306 | N39: -87.7238 | O39: member
A40: 202005-divvy-tripdata.csv | B40: 2020 | C40: 7A50CCAF1EDDB28F | D40: docked_bike | E40: 2020-05-25 10:47:11 | F40: 2020-05-25 11:05:40 | G40: Clark St & Wrightwood Ave | H40: 340 | I40: Clark St & Leland Ave | J40: 326 | K40: 41.9295 | L40: -87.6431 | M40: 41.9671 | N40: -87.6674 | O40: casual
...
